Workbook

Sheet Resumen
A1: Bachoco: plantas, cuentas en el CRM y oportunidades
A2: Cruce de las 21 cuentas Bachoco del CRM contra el inventario público de plantas, con el historial de oportunidades. Documento de trabajo del 15-oct-2026. Los casos se sustentan solo con oportunidades Elegibles (regla del programa). Los montos son potencial anual registrado, no facturación. Ninguna réplica está confirmada.
A4: Cuentas y plantas (se calculan de las otras hojas)
A5: Indicador | B5: Valor | D5: Cómo se lee
A6: Cuentas Bachoco dadas de alta en el CRM | B6: =COUNTA('Cuentas CRM y homologación'!$B$2:$B$22) -> 21 | D6: Las 21 que pasaste en el archivo Workspace_1.csv.
A7: con sitio público confirmado por domicilio | B7: =COUNTIF('Cuentas CRM y homologación'!$X$2:$X$22,"Sí*") -> 6 | D7: Incluye una cuenta duplicada de Culiacán.
A8: con sitio público por confirmar | B8: =COUNTIF('Cuentas CRM y homologación'!$X$2:$X$22,"Por confirmar*") -> 6 | D8: Hay un sitio parecido (misma ciudad o mismo nombre de complejo), pero el domicilio no coincide o no está publicado.
A9: sin sitio público identificado | B9: =COUNTIF('Cuentas CRM y homologación'!$W$2:$W$22,"Sin sitio*") -> 9 | D9: Ninguna fuente pública las confirma. No quiere decir que no existan.
A10: Filas de la lista pública de Bachoco | B10: =COUNTA('Plantas vs CRM'!$A$2:$A$43) -> 42 | D10: Incluye 1 fila agregada (oficinas regionales de 9 ciudades) y 1 sitio no identificado. Bachoco no publica dónde están la mayoría de sus plantas de alimento e incubadoras.
A11: con cuenta en el CRM | B11: =COUNTIF('Plantas vs CRM'!$K$2:$K$43,"Sí*") -> 5 | D11: Cruce por domicilio.
A12: con cuenta por confirmar | B12: =COUNTIF('Plantas vs CRM'!$K$2:$K$43,"Por confirmar*") -> 6 | D12: Cuenta parecida (misma ciudad o nombre); domicilio distinto o no publicado.
A13: en el mismo municipio que otro sitio (predio por confirmar) | B13: =COUNTIF('Plantas vs CRM'!$K$2:$K$43,"Mismo*") -> 7 | D13: Plantas de rendimiento (subproductos) registradas en SADER; comparten municipio con otro sitio (un rastro, o un complejo sin confirmar en Hermosillo); no se sabe si es el mismo predio.
A14: sin cuenta en el CRM | B14: =COUNTIF('Plantas vs CRM'!$K$2:$K$43,"No") -> 22 | D14: No todas son candidatas a dar de alta: ver la columna "Lectura para dar de alta".
A15: de ellas, con fuente confirmada | B15: =COUNTIFS('Plantas vs CRM'!$K$2:$K$43,"No",'Plantas vs CRM'!$J$2:$J$43,"Confirmado") -> 9 | D15: Incluye negocios que no son de aves (cerdo, huevo, CEDIS).
A16: no aplica (fila agregada o sitio no identificado) | B16: =COUNTIF('Plantas vs CRM'!$K$2:$K$43,"No aplica*") -> 2
A18: Oportunidades en cuentas Bachoco
A19: Indicador | B19: Solo Elegible (regla del programa) | C19: Todo el CRM | D19: Cómo se lee
A20: Oportunidades | B20: =COUNTIFS(Oportunidades!$D$2:$D$71,"Sí",Oportunidades!$Z$2:$Z$71,"Elegible") -> 46 | C20: =COUNTIFS(Oportunidades!$D$2:$D$71,"Sí") -> 68 | D20: Ganadas + perdidas + abiertas. Con todo el CRM son 68 en 18 de las 21 cuentas.
A21: Ganadas | B21: =COUNTIFS(Oportunidades!$D$2:$D$71,"Sí",Oportunidades!$Z$2:$Z$71,"Elegible",Oportunidades!$H$2:$H$71,"Ganada") -> 31 | C21: =COUNTIFS(Oportunidades!$D$2:$D$71,"Sí",Oportunidades!$H$2:$H$71,"Ganada") -> 44
A22: Perdidas | B22: =COUNTIFS(Oportunidades!$D$2:$D$71,"Sí",Oportunidades!$Z$2:$Z$71,"Elegible",Oportunidades!$H$2:$H$71,"Perdida") -> 14 | C22: =COUNTIFS(Oportunidades!$D$2:$D$71,"Sí",Oportunidades!$H$2:$H$71,"Perdida") -> 19
A23: Abiertas | B23: =COUNTIFS(Oportunidades!$D$2:$D$71,"Sí",Oportunidades!$Z$2:$Z$71,"Elegible",Oportunidades!$H$2:$H$71,"Abierta") -> 1 | C23: =COUNTIFS(Oportunidades!$D$2:$D$71,"Sí",Oportunidades!$H$2:$H$71,"Abierta") -> 5 | D23: Foto de cartera; no se suman a las ganadas.
A24: Tasa de ganancia (ganadas / (ganadas + perdidas)) | B24: =B21/(B21+B22) -> 0.68888889 | C24: =C21/(C21+C22) -> 0.6984127 | D24: Las abiertas no cuentan.
A25: Potencial anual de las ganadas, suma bruta (MXN) | B25: =SUMIFS(Oportunidades!$K$2:$K$71,Oportunidades!$D$2:$D$71,"Sí",Oportunidades!$Z$2:$Z$71,"Elegible",Oportunidades!$H$2:$H$71,"Ganada") -> 10591086 | C25: =SUMIFS(Oportunidades!$K$2:$K$71,Oportunidades!$D$2:$D$71,"Sí",Oportunidades!$H$2:$H$71,"Ganada") -> 18956616 | D25: Potencial anual registrado, NO facturación; puede repetir el mismo negocio año con año.
A26: Potencial anual de las ganadas, sin posibles re-registros (MXN) | B26: =SUMIFS(Oportunidades!$K$2:$K$71,Oportunidades!$D$2:$D$71,"Sí",Oportunidades!$Z$2:$Z$71,"Elegible",Oportunidades!$H$2:$H$71,"Ganada",Oportunidades!$L$2:$L$71,"No") -> 9318210.5 | C26: =SUMIFS(Oportunidades!$K$2:$K$71,Oportunidades!$D$2:$D$71,"Sí",Oportunidades!$H$2:$H$71,"Ganada",Oportunidades!$L$2:$L$71,"No") -> 17245843 | D26: Quita ganadas que repiten el monto de otra en la misma zona (pista, no confirmación).
A27: Última oportunidad ganada registrada | B27: =_xlfn.MAXIFS(Oportunidades!$I$2:$I$71,Oportunidades!$D$2:$D$71,"Sí",Oportunidades!$Z$2:$Z$71,"Elegible",Oportunidades!$H$2:$H$71,"Ganada") -> 46216 | C27: =_xlfn.MAXIFS(Oportunidades!$I$2:$I$71,Oportunidades!$D$2:$D$71,"Sí",Oportunidades!$H$2:$H$71,"Ganada") -> 46227 | D27: Fecha de cierre más reciente entre las ganadas.
A29: Cifras que Bachoco declara (no son sitios; no sumar)
A30: Indicador | B30: Valor | D30: Fuente y fecha
A31: Plantas procesadoras de pollo en México | B31: 7 | D31: Reporte Anual 2023 (BMV), al 31-dic-2023, publicado 2024-04/05 (fecha exacta ND): https://www.bmv.com.mx/docs-pub/infoanua/infoanua_1378033_2023_1.pdf. SENASICA 2024 muestra solo 6 rastros de aves de Bachoco. CONFIRMADO como cifra declarada.
A32: Plantas de alimento balanceado | B32: 23 (Reporte Anual 2023); 22 (HIPÓTESIS) | D32: Reporte Anual 2023 (misma URL): CONFIRMADO como cifra declarada; el mismo documento dice 25 en el texto (incluye 2 en EUA). La cifra 22 viene del archivo previo GRUPOS_RANKING.csv, que la atribuye al Informe Anual 2024 (https://grupobachoco.com/wp-content/downloads/2025/Informe-Anual-2024-BMV.pdf, fecha de publicación ND): no pude reabrirlo; atribución no verificada. Ese mismo archivo da 10 procesadoras y 66 centros de distribución, que no cuadran con el Reporte Anual 2023 (7 y más de 100), así que podría ser un documento más antiguo.
A33: Incubadoras | B33: 20 (Reporte Anual 2023); 23 (HIPÓTESIS) | D33: Reporte Anual 2023: CONFIRMADO como cifra declarada. La cifra 23 es del archivo previo GRUPOS_RANKING.csv (atribución no verificada, ver arriba). Otro archivo previo (COMPLEJOS_INTEGRADOS.csv) cita "aprox. 20 de alimento y 24 incubadoras" de fuentes más antiguas. Cifras en conflicto: no se eligió una.
A34: Plantas procesadoras de cerdos / empacadoras (valor agregado) | B34: 4 / 4 | D34: Reporte Anual 2023 (misma URL), al 31-dic-2023.
A35: Centros de distribución en México | B35: más de 100 | D35: Reporte Anual 2023 y 1T25 (https://grupobachoco.com/wp-content/downloads/2025/1T25-BMV.pdf, 2025-04-25). Documentos anteriores dicen 66 y más de 80.
A37: Lo más importante
A38: 1. [CONFIRMADO en el CRM] Bachoco tiene 68 oportunidades en 18 de las 21 cuentas (3 cuentas no tienen ninguna). Siguiendo la regla del programa solo cuentan las Elegibles: 46, de las que 31 son ganadas, 14 perdidas y 1 abierta, con tasa de ganancia de 69%. Su potencial anual registrado suma 10.6 millones de pesos bruto, o 9.3 millones quitando 3 posibles re-registros; no es venta facturada. Las otras 22 oportunidades (13 ganadas, 5 perdidas, 1 abierta y 3 sin decisión por ser posteriores al corte) no entran en el análisis y están en la hoja Clasificación dudosa. Con todo el CRM serían 44 ganadas, 19 perdidas y 5 abiertas.
A39: 2. [CONFIRMADO: estatus y conteo; HIPÓTESIS: la línea de las 5 ganadas que solo dicen "PTI"] Con Elegibles, lo que se gana es la banda en V: 23 ganadas contra 2 perdidas. Manguera industrial: 5 y 1. Manguera hidráulica y neumática: 1 y 4. Bandas síncronas, de poliuretano y micro-V: 1 y 6. De las 23 ganadas de banda en V, 13 se clasificaron por abreviatura (PTI, V-Belts) y no por el sufijo de línea del CRM.
A40: 3. [CONFIRMADO] El Bajío (Celaya) concentra 14 de las 31 ganadas Elegibles, 13 de banda en V y ninguna de manguera. Su última ganada es de junio de 2024 y 11 de esas 14 están a nombre de un propietario marcado inactivo en el CRM.
A41: 4. [CONFIRMADO] Tecamachalco es la cuenta que sigue ganando: 10 ganadas Elegibles (banda en V y manguera industrial Plant Master), la más reciente de julio de 2026. 4 de las 5 ganadas Elegibles de manguera industrial son de Tecamachalco.
A42: 5. [CONFIRMADO en el CRM; clasificación dudosa reportada, no cambiada] Culiacán (tu cuenta) tiene 6 ganadas en el CRM, 5 de manguera y 1 de banda en V, pero ninguna es Elegible: 5 quedaron Excluidas porque la cuenta está segmentada como OEM y 1 está en Revisar (cuenta duplicada, segmentación Corporate). Mientras no se corrija esa clasificación, Culiacán no puede sustentar un caso. Todas están en la hoja Clasificación dudosa.
A43: 6. [CONFIRMADO; motivo no disponible] Noroeste (Obregón, Hermosillo y Mexicali): 6 perdidas Elegibles y ninguna ganada (7 perdidas con todo el CRM). Gómez Palacio: 1 perdida. El CRM no tiene campo de motivo de pérdida.
A44: 7. [CONFIRMADO] Ganadas Elegibles por año de cierre: 2 en 2019, 9 en 2020, 5 en 2021, 5 en 2022, 4 en 2023, 4 en 2024, 1 en 2025, 1 en 2026 (2026 es parcial). No se sabe si bajó la actividad con Bachoco o solo la captura en el CRM.
...

Sheet Plantas vs CRM
A1: ID sitio | B1: Tipo de instalación | C1: Nombre público | D1: Municipio | E1: Estado | F1: Domicilio público | G1: Capacidad publicada | H1: Fuente (URL) | I1: Fecha de publicación de la fuente | J1: Verificación de la fuente | K1: ¿Tenemos cuenta en el CRM? | L1: Cuenta(s) CRM relacionada(s) | M1: Base del cruce | N1: Ganadas (todo el CRM) | O1: Perdidas (todo el CRM) | P1: Abiertas (todo el CRM) | Q1: Ganadas Elegibles | R1: Perdidas Elegibles | S1: Observaciones | T1: Lectura para dar de alta en el CRM
A2: BCH-001 | B2: Oficina corporativa | C2: Oficinas corporativas Grupo Bachoco (Industrias Bachoco, S.A. de C.V.) | D2: Celaya | E2: Guanajuato | F2: Avenida Tecnológico No. 401, Ciudad Industrial, C.P. 38010 | G2: ND | H2: https://www.bmv.com.mx/docs-pub/infoanua/infoanua_1378033_2023_1.pdf | https://www.bmv.com.mx/en/issuers/profile/BACHOCO-5113 | https://bachoco.com/aviso-de-privacidad.html | https://www.sec.gov/Archives/edgar/data/1044896/000141057822001105/iba-20211231x20f.htm | I2: 2024-04/05 (fecha exacta ND) | ND (perfil sin fecha) | ND (aviso sin fecha; pie 2025) | 2022-04-29 | J2: Confirmado | K2: Sí | L2: Bachoco S.A. de C.V. - Corp | M2: Domicilio coincide: Av. Tecnológico No. 401, Ciudad Industrial, CP 38010, Celaya (cuenta "Corp"). La verificó la lista pública con el Reporte Anual 2023, el perfil de la BMV y el aviso de privacidad de bachoco.com. | N2: =SUMIFS('Cuentas CRM y homologación'!$P$2:$P$22,'Cuentas CRM y homologación'!$W$2:$W$22,$A2) -> 1 | O2: =SUMIFS('Cuentas CRM y homologación'!$Q$2:$Q$22,'Cuentas CRM y homologación'!$W$2:$W$22,$A2) -> 0 | P2: =SUMIFS('Cuentas CRM y homologación'!$R$2:$R$22,'Cuentas CRM y homologación'!$W$2:$W$22,$A2) -> 0 | Q2: =SUMIFS('Cuentas CRM y homologación'!$S$2:$S$22,'Cuentas CRM y homologación'!$W$2:$W$22,$A2) -> 1 | R2: =SUMIFS('Cuentas CRM y homologación'!$T$2:$T$22,'Cuentas CRM y homologación'!$W$2:$W$22,$A2) -> 0 | S2: La cuenta "Corp" SÍ es el corporativo por domicilio. Ojo: su segmentación en el CRM es End User; la segmentación "Corporate" está en una cuenta de Culiacán. | T2: -
A3: BCH-002 | B3: Oficinas regionales (fila agregada) | C3: Oficinas regionales de ex complejos productivos (hoy Unidades de Negocio) - fila agregada de 9 ciudades | D3: Mérida; Coatzacoalcos; Tecamachalco; Celaya; Lagos de Moreno; Monterrey; Gómez Palacio; Culiacán; Hermosillo | E3: Yucatán; Veracruz; Puebla; Guanajuato; Jalisco; Nuevo León; Durango; Sinaloa; Sonora | F3: PENDIENTE | G3: ND | H3: https://www.bmv.com.mx/docs-pub/infoanua/infoanua_1378033_2023_1.pdf | https://www.sec.gov/Archives/edgar/data/1044896/000114420419021974/tv518925_20f.htm | I3: 2024-04/05 (fecha exacta ND) | 2019-04-29 | J3: Confirmado | K3: No aplica (fila agregada) | L3: - | M3: Fila agregada de 9 ciudades (Mérida, Coatzacoalcos, Tecamachalco, Celaya, Lagos de Moreno, Monterrey, Gómez Palacio, Culiacán, Hermosillo) donde Bachoco tenía oficinas de complejo; hoy son "Unidades de Negocio". No son oficinas corporativas y no publican domicilio. Hay cuentas del CRM en Mérida, Coatzacoalcos, Tecamachalco, Celaya, Gómez Palacio, Culiacán y Hermosillo; no se puede saber si alguna es la oficina. | N3: =SUMIFS('Cuentas CRM y homologación'!$P$2:$P$22,'Cuentas CRM y homologación'!$W$2:$W$22,$A3) -> 0 | O3: =SUMIFS('Cuentas CRM y homologación'!$Q$2:$Q$22,'Cuentas CRM y homologación'!$W$2:$W$22,$A3) -> 0 | P3: =SUMIFS('Cuentas CRM y homologación'!$R$2:$R$22,'Cuentas CRM y homologación'!$W$2:$W$22,$A3) -> 0 | Q3: =SUMIFS('Cuentas CRM y homologación'!$S$2:$S$22,'Cuentas CRM y homologación'!$W$2:$W$22,$A3) -> 0 | R3: =SUMIFS('Cuentas CRM y homologación'!$T$2:$T$22,'Cuentas CRM y homologación'!$W$2:$W$22,$A3) -> 0 | S3: Vigencia a 2026 no verificada (fuentes de 2024 y 2019). | T3: -
A4: BCH-010 | B4: Procesadora de aves (rastro TIF) | C4: Rastro / planta procesadora de aves TIF A-363 (División Bajío) | D4: Celaya | E4: Guanajuato | F4: Km. 5 Carretera Celaya-Salamanca, Segunda Fracción de Crespo, C.P. 38020 | G4: ND | H4: https://campo.nl.gob.mx/pdf/directorios/Directorio_TIF.pdf | https://www.am.com.mx/celaya/2023/3/1/drenaje-tapado-de-rastro-de-bachoco-causaria-malos-olores-en-celaya-649603.html | https://www.agricultura.gob.mx/sites/default/files/sagarpa/document/2025/12/04/2250/04122025-padron-plantas-rendimiento.csv | I4: 2024 (año indicado en el documento; fecha exacta ND) | 2023-03-01 | 2025-12-04 (inferida de la ruta del URL) | J4: Confirmado | K4: Por confirmar | L4: Bachoco, S.A. de C.V. - Planta procesadora de aves Guanajuato - Guanajuato | M4: La cuenta "Planta procesadora de aves Guanajuato - Guanajuato" tiene domicilio "Av el Vergel, San Isidro Crespo" (CP 36003). Directorios comerciales ubican el rastro en "Parque Industrial El Vergel" y "San Isidro de Crespo", pero el domicilio oficial de SENASICA es Km 5 Carr. Celaya-Salamanca, Segunda Fracción de Crespo (CP 38020). El CP del CRM no coincide. | N4: =SUMIFS('Cuentas CRM y homologación'!$P$2:$P$22,'Cuentas CRM y homologación'!$W$2:$W$22,$A4) -> 11 | O4: =SUMIFS('Cuentas CRM y homologación'!$Q$2:$Q$22,'Cuentas CRM y homologación'!$W$2:$W$22,$A4) -> 3 | P4: =SUMIFS('Cuentas CRM y homologación'!$R$2:$R$22,'Cuentas CRM y homologación'!$W$2:$W$22,$A4) -> 0 | Q4: =SUMIFS('Cuentas CRM y homologación'!$S$2:$S$22,'Cuentas CRM y homologación'!$W$2:$W$22,$A4) -> 10 | R4: =SUMIFS('Cuentas CRM y homologación'!$T$2:$T$22,'Cuentas CRM y homologación'!$W$2:$W$22,$A4) -> 3 | S4: Mismo nombre de lugar (Crespo / El Vergel), domicilio distinto: falta confirmar en visita. Es la cuenta con más ganadas (11 en todo el CRM, 10 Elegibles). | T4: -
A5: BCH-011 | B5: Procesadora de aves (rastro TIF) | C5: Rastro / planta procesadora de aves TIF A-183 (División Occidente, conocida como 'Lagos de Moreno') | D5: Unión de San Antonio | E5: Jalisco | F5: Carretera Lagos - U. de San Antonio Km. 13.5, Unión de San Antonio, C.P. 47570 | G5: ND | H5: https://campo.nl.gob.mx/pdf/directorios/Directorio_TIF.pdf | https://www.agricultura.gob.mx/sites/default/files/sagarpa/document/2025/12/04/2250/04122025-padron-plantas-rendimiento.csv | I5: 2024 (año indicado en el documento; fecha exacta ND) | 2025-12-04 (inferida de la ruta del URL) | J5: Confirmado | K5: No | L5: - | M5: No hay cuenta del CRM en Unión de San Antonio ni en Lagos de Moreno. | N5: =SUMIFS('Cuentas CRM y homologación'!$P$2:$P$22,'Cuentas CRM y homologación'!$W$2:$W$22,$A5) -> 0 | O5: =SUMIFS('Cuentas CRM y homologación'!$Q$2:$Q$22,'Cuentas CRM y homologación'!$W$2:$W$22,$A5) -> 0 | P5: =SUMIFS('Cuentas CRM y homologación'!$R$2:$R$22,'Cuentas CRM y homologación'!$W$2:$W$22,$A5) -> 0 | Q5: =SUMIFS('Cuentas CRM y homologación'!$S$2:$S$22,'Cuentas CRM y homologación'!$W$2:$W$22,$A5) -> 0 | R5: =SUMIFS('Cuentas CRM y homologación'!$T$2:$T$22,'Cuentas CRM y homologación'!$W$2:$W$22,$A5) -> 0 | S5: La oportunidad O-00218689 "7.1 PCC C2B-Bachoco Lagos- Bamac Guadalajara" (perdida, 2020) está capturada en la cuenta de Celaya/Guanajuato, no en una cuenta propia de Lagos; que se refiera a este sitio es HIPÓTESIS (solo por el nombre). El 2026-05-03 hubo un incendio en una planta de Lagos de Moreno (ver BCH-012); no está confirmado que sea este predio. | T5: Fuente confirmada: candidato a dar de alta si interesa.
A6: BCH-012 | B6: Procesadora de aves | C6: Planta Bachoco en Lagos de Moreno (siniestrada el 2026-05-03) | D6: Lagos de Moreno | E6: Jalisco | F6: Autopista León-Aguascalientes, cruce con Ramal Paso de la Mesa (descripción de prensa citando a Protección Civil Jalisco; sin calle ni km) | G6: ND | H6: https://lasillarota.com/guanajuato/estado/2026/5/11/tras-incendio-en-planta-de-bachoco-trabajadores-son-reubicados-en-celaya-puebla-nl-598777.html | https://www.elfinanciero.com.mx/estados/2026/05/04/incendio-en-planta-de-bachoco-en-lagos-de-moreno-deja-3-personas-intoxicadas-esto-sabemos/ | https://www.milenio.com/comunidad/bachoco-suspende-operaciones-incendio-trabajadores-reubicados | https://www.unotv.com/estados/jalisco/fuego-devora-planta-de-bachoco-en-lagos-de-moreno-jalisco-videos/ | I6: 2026-05-11 | 2026-05-04 | 2026-05-05 | 2026-05-04 | J6: Hipótesis | K6: No | L6: - | M6: No hay cuenta del CRM en Lagos de Moreno. | N6: =SUMIFS('Cuentas CRM y homologación'!$P$2:$P$22,'Cuentas CRM y homologación'!$W$2:$W$22,$A6) -> 0 | O6: =SUMIFS('Cuentas CRM y homologación'!$Q$2:$Q$22,'Cuentas CRM y homologación'!$W$2:$W$22,$A6) -> 0 | P6: =SUMIFS('Cuentas CRM y homologación'!$R$2:$R$22,'Cuentas CRM y homologación'!$W$2:$W$22,$A6) -> 0 | Q6: =SUMIFS('Cuentas CRM y homologación'!$S$2:$S$22,'Cuentas CRM y homologación'!$W$2:$W$22,$A6) -> 0 | R6: =SUMIFS('Cuentas CRM y homologación'!$T$2:$T$22,'Cuentas CRM y homologación'!$W$2:$W$22,$A6) -> 0 | S6: Fuente: solo prensa. Posible duplicado de BCH-011: la ubicación descrita por la prensa (autopista León-Aguascalientes) no es la del TIF (carretera a Unión de San Antonio). Reapertura PENDIENTE. | T6: Posible duplicado de BCH-011: no dar de alta por separado.
A7: BCH-013 | B7: Procesadora de aves (rastro TIF) | C7: Rastro / planta procesadora de aves TIF A-423 (Complejo Noreste / Monterrey) | D7: Ciénega de Flores | E7: Nuevo León | F7: Autopista Monterrey-Nuevo Laredo Km. 34+200, C.P. 65550 | G7: ND | H7: https://campo.nl.gob.mx/pdf/directorios/Directorio_TIF.pdf | https://www.agricultura.gob.mx/sites/default/files/sagarpa/document/2025/12/04/2250/04122025-padron-plantas-rendimiento.csv | I7: 2024 (año indicado en el documento; fecha exacta ND) | 2025-12-04 (inferida de la ruta del URL) | J7: Confirmado | K7: Sí | L7: BACHOCO SA de CV - Cienega de Flores | M7: Domicilio coincide en carretera y kilómetro: Autopista Monterrey-Nuevo Laredo Km 34 (CP 65555 en el CRM; 65550 en SENASICA). | N7: =SUMIFS('Cuentas CRM y homologación'!$P$2:$P$22,'Cuentas CRM y homologación'!$W$2:$W$22,$A7) -> 1 | O7: =SUMIFS('Cuentas CRM y homologación'!$Q$2:$Q$22,'Cuentas CRM y homologación'!$W$2:$W$22,$A7) -> 0 | P7: =SUMIFS('Cuentas CRM y homologación'!$R$2:$R$22,'Cuentas CRM y homologación'!$W$2:$W$22,$A7) -> 1 | Q7: =SUMIFS('Cuentas CRM y homologación'!$S$2:$S$22,'Cuentas CRM y homologación'!$W$2:$W$22,$A7) -> 0 | R7: =SUMIFS('Cuentas CRM y homologación'!$T$2:$T$22,'Cuentas CRM y homologación'!$W$2:$W$22,$A7) -> 0 | S7: Cuenta creada el 6-abr-2026, con 1 ganada (jul-2026) y 1 abierta. | T7: -
A8: BCH-014 | B8: Procesadora de aves (rastro TIF) | C8: Rastro / planta procesadora de aves TIF A-326 (Complejo Sureste, 'Tecamachalco') | D8: San Salvador Huixcolotla | E8: Puebla | F8: Carretera Federal Puebla-Tehuacán Km. 53, San Salvador Huixcolotla, C.P. 75440 | G8: ND | H8: https://campo.nl.gob.mx/pdf/directorios/Directorio_TIF.pdf | https://www.agricultura.gob.mx/sites/default/files/sagarpa/document/2025/12/04/2250/04122025-padron-plantas-rendimiento.csv | I8: 2024 (año indicado en el documento; fecha exacta ND) | 2025-12-04 (inferida de la ruta del URL) | J8: Confirmado | K8: Por confirmar | L8: Bachoco, S.A. De C.V. - Tecamachalco | M8: El predio oficial del rastro está en San Salvador Huixcolotla (Km 53 Puebla-Tehuacán, CP 75440); "Tecamachalco" es el nombre histórico del complejo. La cuenta del CRM dice Tecamachalco, Barrio de San Juan (CP 75484), domicilio que viene de directorios no oficiales. | N8: =SUMIFS('Cuentas CRM y homologación'!$P$2:$P$22,'Cuentas CRM y homologación'!$W$2:$W$22,$A8) -> 10 | O8: =SUMIFS('Cuentas CRM y homologación'!$Q$2:$Q$22,'Cuentas CRM y homologación'!$W$2:$W$22,$A8) -> 5 | P8: =SUMIFS('Cuentas CRM y homologación'!$R$2:$R$22,'Cuentas CRM y homologación'!$W$2:$W$22,$A8) -> 0 | Q8: =SUMIFS('Cuentas CRM y homologación'!$S$2:$S$22,'Cuentas CRM y homologación'!$W$2:$W$22,$A8) -> 10 | R8: =SUMIFS('Cuentas CRM y homologación'!$T$2:$T$22,'Cuentas CRM y homologación'!$W$2:$W$22,$A8) -> 3 | S8: Misma operación por nombre de complejo, domicilio distinto. Falta confirmar en visita si la cuenta es el rastro de Huixcolotla. | T8: -
A9: BCH-015 | B9: Procesadora de aves (rastro TIF) | C9: Rastro / planta procesadora de aves TIF A-124 (Complejo Noroeste) | D9: Culiacán | E9: Sinaloa | F9: Carretera al Dorado Km. 13.5, Culiacán, C.P. 80100 (Apartado Postal 607) | G9: ND | H9: https://campo.nl.gob.mx/pdf/directorios/Directorio_TIF.pdf | https://www.agricultura.gob.mx/sites/default/files/sagarpa/document/2025/12/04/2250/04122025-padron-plantas-rendimiento.csv | I9: 2024 (año indicado en el documento; fecha exacta ND) | 2025-12-04 (inferida de la ruta del URL) | J9: Confirmado | K9: Sí | L9: Bachoco S.A. de C.V. - Planta Culiacan | BACHOCO Planta Culiacan | M9: Domicilio coincide: Carretera al Dorado Km 13.5, Culiacán. Las dos cuentas del CRM de Culiacán tienen el mismo domicilio (CP 80300 y 80130; SENASICA 80100). | N9: =SUMIFS('Cuentas CRM y homologación'!$P$2:$P$22,'Cuentas CRM y homologación'!$W$2:$W$22,$A9) -> 6 | O9: =SUMIFS('Cuentas CRM y homologación'!$Q$2:$Q$22,'Cuentas CRM y homologación'!$W$2:$W$22,$A9) -> 2 | P9: =SUMIFS('Cuentas CRM y homologación'!$R$2:$R$22,'Cuentas CRM y homologación'!$W$2:$W$22,$A9) -> 0 | Q9: =SUMIFS('Cuentas CRM y homologación'!$S$2:$S$22,'Cuentas CRM y homologación'!$W$2:$W$22,$A9) -> 0 | R9: =SUMIFS('Cuentas CRM y homologación'!$T$2:$T$22,'Cuentas CRM y homologación'!$W$2:$W$22,$A9) -> 0 | S9: Dos cuentas para el mismo sitio (una con segmentación OEM, otra Corporate). | T9: -
A10: BCH-016 | B10: Procesadora de aves (rastro TIF) | C10: Rastro / planta procesadora de aves TIF A-234 (Complejo Península) | D10: Mérida (SENASICA) / Umán (SADER y CP 97390) | E10: Yucatán | F10: Carr. Mérida-Umán Km. 14.5, C.P. 97390 | G10: ND | H10: https://campo.nl.gob.mx/pdf/directorios/Directorio_TIF.pdf | https://www.agricultura.gob.mx/sites/default/files/sagarpa/document/2025/12/04/2250/04122025-padron-plantas-rendimiento.csv | https://www.poresto.com/yucatan/2026/2/16/joaquin-diaz-mena-impulsa-mayor-inversion-empresarial-para-generar-empleos-en-yucatan.html | I10: 2024 (año indicado en el documento; fecha exacta ND) | 2025-12-04 (inferida de la ruta del URL) | 2026-02-16 | J10: Confirmado | K10: Sí | L10: Industrias Bachoco S.A. de C.V. - Uman, Yucatan. | M10: Domicilio coincide: Carretera Mérida-Umán Km 14.5, CP 97390 (cuenta "Industrias Bachoco ... Umán"). SENASICA lo llama Mérida; el CP es de Umán. | N10: =SUMIFS('Cuentas CRM y homologación'!$P$2:$P$22,'Cuentas CRM y homologación'!$W$2:$W$22,$A10) -> 1 | O10: =SUMIFS('Cuentas CRM y homologación'!$Q$2:$Q$22,'Cuentas CRM y homologación'!$W$2:$W$22,$A10) -> 0 | P10: =SUMIFS('Cuentas CRM y homologación'!$R$2:$R$22,'Cuentas CRM y homologación'!$W$2:$W$22,$A10) -> 0 | Q10: =SUMIFS('Cuentas CRM y homologación'!$S$2:$S$22,'Cuentas CRM y homologación'!$W$2:$W$22,$A10) -> 1 | R10: =SUMIFS('Cuentas CRM y homologación'!$T$2:$T$22,'Cuentas CRM y homologación'!$W$2:$W$22,$A10) -> 0 | S10: Mérida y Umán son el mismo rastro. La cuenta "Industrias Bachoco ... Mérida" (Calle Benito Juárez 21) NO es este domicilio. | T10: -
A11: BCH-017 | B11: Procesadora de aves | C11: Séptima planta procesadora de pollo declarada (no identificada) | D11: PENDIENTE | E11: PENDIENTE | F11: PENDIENTE | G11: ND | H11: https://www.bmv.com.mx/docs-pub/infoanua/infoanua_1378033_2023_1.pdf | I11: 2024-04/05 (fecha exacta ND) | J11: Pendiente | K11: No aplica | L11: - | M11: Sitio no identificado. | N11: =SUMIFS('Cuentas CRM y homologación'!$P$2:$P$22,'Cuentas CRM y homologación'!$W$2:$W$22,$A11) -> 0 | O11: =SUMIFS('Cuentas CRM y homologación'!$Q$2:$Q$22,'Cuentas CRM y homologación'!$W$2:$W$22,$A11) -> 0 | P11: =SUMIFS('Cuentas CRM y homologación'!$R$2:$R$22,'Cuentas CRM y homologación'!$W$2:$W$22,$A11) -> 0 | Q11: =SUMIFS('Cuentas CRM y homologación'!$S$2:$S$22,'Cuentas CRM y homologación'!$W$2:$W$22,$A11) -> 0 | R11: =SUMIFS('Cuentas CRM y homologación'!$T$2:$T$22,'Cuentas CRM y homologación'!$W$2:$W$22,$A11) -> 0 | S11: El Reporte Anual 2023 declara 7 plantas de pollo y SENASICA muestra 6 rastros de aves a nombre de Bachoco. | T11: -
A12: BCH-018 | B12: Complejo sin confirmar | C12: Complejo Hermosillo (planta procesadora de aves y/o planta de alimento: no confirmadas) | D12: Hermosillo | E12: Sonora | F12: PENDIENTE | G12: ND | H12: https://www.bmv.com.mx/docs-pub/infoanua/infoanua_1378033_2023_1.pdf | https://www.agricultura.gob.mx/sites/default/files/sagarpa/document/2025/12/04/2250/04122025-padron-plantas-rendimiento.csv | I12: 2024-04/05 (fecha exacta ND) | 2025-12-04 (inferida de la ruta del URL) | J12: Pendiente | K12: Por confirmar | L12: Bchoco S.A. de C.V. - Planta Hermosillo | M12: La cuenta "Bchoco ... Hermosillo" (Carretera Sahurita Km 3.5, Parque Industrial, CP 83299, tal como está en el CRM) coincide en ciudad con el ex complejo Hermosillo. No hay domicilio verificado de la planta de aves. | N12: =SUMIFS('Cuentas CRM y homologación'!$P$2:$P$22,'Cuentas CRM y homologación'!$W$2:$W$22,$A12) -> 0 | O12: =SUMIFS('Cuentas CRM y homologación'!$Q$2:$Q$22,'Cuentas CRM y homologación'!$W$2:$W$22,$A12) -> 1 | P12: =SUMIFS('Cuentas CRM y homologación'!$R$2:$R$22,'Cuentas CRM y homologación'!$W$2:$W$22,$A12) -> 0 | Q12: =SUMIFS('Cuentas CRM y homologación'!$S$2:$S$22,'Cuentas CRM y homologación'!$W$2:$W$22,$A12) -> 0 | R12: =SUMIFS('Cuentas CRM y homologación'!$T$2:$T$22,'Cuentas CRM y homologación'!$W$2:$W$22,$A12) -> 1 | S12: El CP 83299 es el mismo del rastro porcino TIF 66 de Norson (BCH-032): riesgo de mezclar sitios. Confirmar en visita qué instalación es. | T12: -
A13: BCH-019 | B13: Complejo sin confirmar | C13: Planta procesadora de aves Coatzacoalcos (Complejo Istmo): operación actual no confirmada | D13: Coatzacoalcos | E13: Veracruz | F13: PENDIENTE | G13: ND | H13: https://www.bmv.com.mx/docs-pub/infoanua/infoanua_1378033_2023_1.pdf | https://rinacional.tecnm.mx/handle/TecNM/6281 | I13: 2024-04/05 (fecha exacta ND) | 2009-05 | J13: Pendiente | K13: Por confirmar | L13: Bachoco, S.A. de C.V. - Planta Coatzacoalcos | M13: La cuenta "Planta Coatzacoalcos" (Carretera Transístmica Km 7.5) coincide en ciudad con el ex complejo Coatzacoalcos. La única evidencia pública de operación es una tesis de 2009. | N13: =SUMIFS('Cuentas CRM y homologación'!$P$2:$P$22,'Cuentas CRM y homologación'!$W$2:$W$22,$A13) -> 1 | O13: =SUMIFS('Cuentas CRM y homologación'!$Q$2:$Q$22,'Cuentas CRM y homologación'!$W$2:$W$22,$A13) -> 1 | P13: =SUMIFS('Cuentas CRM y homologación'!$R$2:$R$22,'Cuentas CRM y homologación'!$W$2:$W$22,$A13) -> 0 | Q13: =SUMIFS('Cuentas CRM y homologación'!$S$2:$S$22,'Cuentas CRM y homologación'!$W$2:$W$22,$A13) -> 1 | R13: =SUMIFS('Cuentas CRM y homologación'!$T$2:$T$22,'Cuentas CRM y homologación'!$W$2:$W$22,$A13) -> 1 | S13: Tiene 1 ganada (2024) y 1 perdida (2025) registradas en el CRM. Falta confirmar qué instalación es. | T13: -
A14: BCH-020 | B14: Planta de rendimiento (subproductos) | C14: Planta de rendimiento Bachoco - Celaya | D14: Celaya | E14: Guanajuato | F14: PENDIENTE (el padrón solo da municipio y CP 38010) | G14: ND | H14: https://www.agricultura.gob.mx/sites/default/files/sagarpa/document/2025/12/04/2250/04122025-padron-plantas-rendimiento.csv | I14: 2025-12-04 (inferida de la ruta del URL) | J14: Confirmado | K14: Mismo municipio que BCH-010; predio por confirmar | L14: - | M14: Planta de rendimiento (subproductos) registrada en SADER en Celaya con CP 38010; el rastro BCH-010 tiene CP 38020. No se sabe si es el mismo predio. | N14: =SUMIFS('Cuentas CRM y homologación'!$P$2:$P$22,'Cuentas CRM y homologación'!$W$2:$W$22,$A14) -> 0 | O14: =SUMIFS('Cuentas CRM y homologación'!$Q$2:$Q$22,'Cuentas CRM y homologación'!$W$2:$W$22,$A14) -> 0 | P14: =SUMIFS('Cuentas CRM y homologación'!$R$2:$R$22,'Cuentas CRM y homologación'!$W$2:$W$22,$A14) -> 0 | Q14: =SUMIFS('Cuentas CRM y homologación'!$S$2:$S$22,'Cuentas CRM y homologación'!$W$2:$W$22,$A14) -> 0 | R14: =SUMIFS('Cuentas CRM y homologación'!$T$2:$T$22,'Cuentas CRM y homologación'!$W$2:$W$22,$A14) -> 0 | S14: Las cuentas 2, 4 (Corp) y 6 del CRM también tienen CP 38010; no basta para ligarlas. | T14: -
A15: BCH-021 | B15: Planta de rendimiento (subproductos) | C15: Planta de rendimiento Bachoco - Hermosillo ('planta sonora') | D15: Hermosillo | E15: Sonora | F15: PENDIENTE (el padrón solo da municipio y CP 83243) | G15: ND | H15: https://www.agricultura.gob.mx/sites/default/files/sagarpa/document/2025/12/04/2250/04122025-padron-plantas-rendimiento.csv | I15: 2025-12-04 (inferida de la ruta del URL) | J15: Confirmado | K15: Mismo municipio que BCH-018; predio por confirmar | L15: - | M15: Planta de rendimiento registrada en SADER en Hermosillo (CP 83243). BCH-018 (complejo Hermosillo) no está confirmado como planta de aves. | N15: =SUMIFS('Cuentas CRM y homologación'!$P$2:$P$22,'Cuentas CRM y homologación'!$W$2:$W$22,$A15) -> 0 | O15: =SUMIFS('Cuentas CRM y homologación'!$Q$2:$Q$22,'Cuentas CRM y homologación'!$W$2:$W$22,$A15) -> 0 | P15: =SUMIFS('Cuentas CRM y homologación'!$R$2:$R$22,'Cuentas CRM y homologación'!$W$2:$W$22,$A15) -> 0 | Q15: =SUMIFS('Cuentas CRM y homologación'!$S$2:$S$22,'Cuentas CRM y homologación'!$W$2:$W$22,$A15) -> 0 | R15: =SUMIFS('Cuentas CRM y homologación'!$T$2:$T$22,'Cuentas CRM y homologación'!$W$2:$W$22,$A15) -> 0 | T15: -
A16: BCH-022 | B16: Planta de rendimiento (subproductos) | C16: Planta de rendimiento Bachoco - Culiacán | D16: Culiacán | E16: Sinaloa | F16: PENDIENTE (el padrón solo da municipio y CP 80110) | G16: ND | H16: https://www.agricultura.gob.mx/sites/default/files/sagarpa/document/2025/12/04/2250/04122025-padron-plantas-rendimiento.csv | I16: 2025-12-04 (inferida de la ruta del URL) | J16: Confirmado | K16: Mismo municipio que BCH-015; predio por confirmar | L16: - | M16: Planta de rendimiento registrada en SADER en Culiacán con CP 80110; el rastro BCH-015 tiene CP 80100. No se sabe si es el mismo predio. | N16: =SUMIFS('Cuentas CRM y homologación'!$P$2:$P$22,'Cuentas CRM y homologación'!$W$2:$W$22,$A16) -> 0 | O16: =SUMIFS('Cuentas CRM y homologación'!$Q$2:$Q$22,'Cuentas CRM y homologación'!$W$2:$W$22,$A16) -> 0 | P16: =SUMIFS('Cuentas CRM y homologación'!$R$2:$R$22,'Cuentas CRM y homologación'!$W$2:$W$22,$A16) -> 0 | Q16: =SUMIFS('Cuentas CRM y homologación'!$S$2:$S$22,'Cuentas CRM y homologación'!$W$2:$W$22,$A16) -> 0 | R16: =SUMIFS('Cuentas CRM y homologación'!$T$2:$T$22,'Cuentas CRM y homologación'!$W$2:$W$22,$A16) -> 0 | T16: -
A17: BCH-023 | B17: Planta de rendimiento (subproductos) | C17: Planta de rendimiento Bachoco - 'planta tecamachalco' (en Huixcolotla) | D17: San Salvador Huixcolotla | E17: Puebla | F17: PENDIENTE (el padrón solo da municipio y CP 75482) | G17: ND | H17: https://www.agricultura.gob.mx/sites/default/files/sagarpa/document/2025/12/04/2250/04122025-padron-plantas-rendimiento.csv | I17: 2025-12-04 (inferida de la ruta del URL) | J17: Confirmado | K17: Mismo municipio que BCH-014; predio por confirmar | L17: - | M17: Planta de rendimiento registrada en SADER en Huixcolotla con CP 75482; el rastro BCH-014 tiene CP 75440. | N17: =SUMIFS('Cuentas CRM y homologación'!$P$2:$P$22,'Cuentas CRM y homologación'!$W$2:$W$22,$A17) -> 0 | O17: =SUMIFS('Cuentas CRM y homologación'!$Q$2:$Q$22,'Cuentas CRM y homologación'!$W$2:$W$22,$A17) -> 0 | P17: =SUMIFS('Cuentas CRM y homologación'!$R$2:$R$22,'Cuentas CRM y homologación'!$W$2:$W$22,$A17) -> 0 | Q17: =SUMIFS('Cuentas CRM y homologación'!$S$2:$S$22,'Cuentas CRM y homologación'!$W$2:$W$22,$A17) -> 0 | R17: =SUMIFS('Cuentas CRM y homologación'!$T$2:$T$22,'Cuentas CRM y homologación'!$W$2:$W$22,$A17) -> 0 | T17: -
A18: BCH-024 | B18: Planta de rendimiento (subproductos) | C18: Planta de rendimiento Bachoco - 'planta lagos' (en Unión de San Antonio) | D18: Unión de San Antonio | E18: Jalisco | F18: PENDIENTE (el padrón solo da municipio y CP 47450) | G18: ND | H18: https://www.agricultura.gob.mx/sites/default/files/sagarpa/document/2025/12/04/2250/04122025-padron-plantas-rendimiento.csv | I18: 2025-12-04 (inferida de la ruta del URL) | J18: Confirmado | K18: Mismo municipio que BCH-011; predio por confirmar | L18: - | M18: Planta de rendimiento registrada en SADER en Unión de San Antonio con CP 47450; el rastro BCH-011 tiene CP 47570 (SENASICA). Dos fuentes oficiales dan CP distinto. | N18: =SUMIFS('Cuentas CRM y homologación'!$P$2:$P$22,'Cuentas CRM y homologación'!$W$2:$W$22,$A18) -> 0 | O18: =SUMIFS('Cuentas CRM y homologación'!$Q$2:$Q$22,'Cuentas CRM y homologación'!$W$2:$W$22,$A18) -> 0 | P18: =SUMIFS('Cuentas CRM y homologación'!$R$2:$R$22,'Cuentas CRM y homologación'!$W$2:$W$22,$A18) -> 0 | Q18: =SUMIFS('Cuentas CRM y homologación'!$S$2:$S$22,'Cuentas CRM y homologación'!$W$2:$W$22,$A18) -> 0 | R18: =SUMIFS('Cuentas CRM y homologación'!$T$2:$T$22,'Cuentas CRM y homologación'!$W$2:$W$22,$A18) -> 0 | T18: -
A19: BCH-025 | B19: Planta de rendimiento (subproductos) | C19: Planta de rendimiento Bachoco - 'planta nuevo leon' (Ciénega de Flores) | D19: Ciénega de Flores | E19: Nuevo León | F19: PENDIENTE (el padrón solo da municipio y CP 65550) | G19: ND | H19: https://www.agricultura.gob.mx/sites/default/files/sagarpa/document/2025/12/04/2250/04122025-padron-plantas-rendimiento.csv | I19: 2025-12-04 (inferida de la ruta del URL) | J19: Confirmado | K19: Mismo municipio que BCH-013; predio por confirmar | L19: - | M19: Planta de rendimiento registrada en SADER en Ciénega de Flores con el mismo CP 65550 que el rastro. Mismo complejo probable (HIPÓTESIS por CP igual). | N19: =SUMIFS('Cuentas CRM y homologación'!$P$2:$P$22,'Cuentas CRM y homologación'!$W$2:$W$22,$A19) -> 0 | O19: =SUMIFS('Cuentas CRM y homologación'!$Q$2:$Q$22,'Cuentas CRM y homologación'!$W$2:$W$22,$A19) -> 0 | P19: =SUMIFS('Cuentas CRM y homologación'!$R$2:$R$22,'Cuentas CRM y homologación'!$W$2:$W$22,$A19) -> 0 | Q19: =SUMIFS('Cuentas CRM y homologación'!$S$2:$S$22,'Cuentas CRM y homologación'!$W$2:$W$22,$A19) -> 0 | R19: =SUMIFS('Cuentas CRM y homologación'!$T$2:$T$22,'Cuentas CRM y homologación'!$W$2:$W$22,$A19) -> 0 | T19: -
A20: BCH-026 | B20: Planta de rendimiento (subproductos) | C20: Planta de rendimiento Bachoco - Umán | D20: Umán | E20: Yucatán | F20: PENDIENTE (el padrón solo da municipio y CP 97390) | G20: ND | H20: https://www.agricultura.gob.mx/sites/default/files/sagarpa/document/2025/12/04/2250/04122025-padron-plantas-rendimiento.csv | I20: 2025-12-04 (inferida de la ruta del URL) | J20: Confirmado | K20: Mismo municipio que BCH-016; predio por confirmar | L20: - | M20: Planta de rendimiento registrada en SADER en Umán con el mismo CP 97390 que el rastro. Mismo complejo probable (HIPÓTESIS por CP igual). | N20: =SUMIFS('Cuentas CRM y homologación'!$P$2:$P$22,'Cuentas CRM y homologación'!$W$2:$W$22,$A20) -> 0 | O20: =SUMIFS('Cuentas CRM y homologación'!$Q$2:$Q$22,'Cuentas CRM y homologación'!$W$2:$W$22,$A20) -> 0 | P20: =SUMIFS('Cuentas CRM y homologación'!$R$2:$R$22,'Cuentas CRM y homologación'!$W$2:$W$22,$A20) -> 0 | Q20: =SUMIFS('Cuentas CRM y homologación'!$S$2:$S$22,'Cuentas CRM y homologación'!$W$2:$W$22,$A20) -> 0 | R20: =SUMIFS('Cuentas CRM y homologación'!$T$2:$T$22,'Cuentas CRM y homologación'!$W$2:$W$22,$A20) -> 0 | T20: -
A21: BCH-030 | B21: Planta porcina (rastro TIF) | C21: Rastro porcino TIF 57 - Sonora Agropecuaria, S.A. de C.V. (SASA) | D21: Navojoa | E21: Sonora | F21: Carretera México-Nogales Km. 1778, Col. Parque Industrial, C.P. 85895 | G21: ND | H21: https://campo.nl.gob.mx/pdf/directorios/Directorio_TIF.pdf | https://www.bmv.com.mx/docs-pub/infoanua/infoanua_1378033_2023_1.pdf | https://bmeditores.mx/porcicultura/rastro-tif-de-sonora-fuera-de-operacion-por-polo-opormex-pide-respuesta-urgente/ | I21: 2024 (año indicado en el documento; fecha exacta ND) | 2024-04/05 (fecha exacta ND) | 2026-10-01 | J21: Confirmado | K21: No | L21: - | M21: Sin cuenta del CRM en Navojoa. | N21: =SUMIFS('Cuentas CRM y homologación'!$P$2:$P$22,'Cuentas CRM y homologación'!$W$2:$W$22,$A21) -> 0 | O21: =SUMIFS('Cuentas CRM y homologación'!$Q$2:$Q$22,'Cuentas CRM y homologación'!$W$2:$W$22,$A21) -> 0 | P21: =SUMIFS('Cuentas CRM y homologación'!$R$2:$R$22,'Cuentas CRM y homologación'!$W$2:$W$22,$A21) -> 0 | Q21: =SUMIFS('Cuentas CRM y homologación'!$S$2:$S$22,'Cuentas CRM y homologación'!$W$2:$W$22,$A21) -> 0 | R21: =SUMIFS('Cuentas CRM y homologación'!$T$2:$T$22,'Cuentas CRM y homologación'!$W$2:$W$22,$A21) -> 0 | S21: Subsidiaria de Bachoco (Sonora Agropecuaria). No es de aves. No confundir con Grupo Kowi (otra empresa, también en Navojoa), cuyo rastro se inundó por el huracán Polo (nota de BM Editores, 2026-10-01); no hay reporte de efectos en la subsidiaria de Bachoco (pendiente). | T21: Fuente confirmada; es el negocio porcino (otra operación).
A22: BCH-031 | B22: Planta porcina (rastro TIF) | C22: Rastro porcino TIF 467 - Sonora Agropecuaria, S.A. de C.V. (SASA) | D22: Atotonilco el Alto | E22: Jalisco | F22: Km. 86.1 Carretera Guadalajara-La Piedad, municipio de Atotonilco el Alto, C.P. 47750 | G22: ND | H22: https://campo.nl.gob.mx/pdf/directorios/Directorio_TIF.pdf | https://www.bmv.com.mx/docs-pub/infoanua/infoanua_1378033_2023_1.pdf | I22: 2024 (año indicado en el documento; fecha exacta ND) | 2024-04/05 (fecha exacta ND) | J22: Confirmado | K22: No | L22: - | M22: Sin cuenta del CRM en Atotonilco el Alto. | N22: =SUMIFS('Cuentas CRM y homologación'!$P$2:$P$22,'Cuentas CRM y homologación'!$W$2:$W$22,$A22) -> 0 | O22: =SUMIFS('Cuentas CRM y homologación'!$Q$2:$Q$22,'Cuentas CRM y homologación'!$W$2:$W$22,$A22) -> 0 | P22: =SUMIFS('Cuentas CRM y homologación'!$R$2:$R$22,'Cuentas CRM y homologación'!$W$2:$W$22,$A22) -> 0 | Q22: =SUMIFS('Cuentas CRM y homologación'!$S$2:$S$22,'Cuentas CRM y homologación'!$W$2:$W$22,$A22) -> 0 | R22: =SUMIFS('Cuentas CRM y homologación'!$T$2:$T$22,'Cuentas CRM y homologación'!$W$2:$W$22,$A22) -> 0 | S22: Subsidiaria de Bachoco (Sonora Agropecuaria); rastro porcino. | T22: Fuente confirmada; es el negocio porcino (otra operación).
A23: BCH-032 | B23: Planta porcina (rastro TIF) | C23: Rastro porcino TIF 66 (Norson; razón social en SENASICA: Frigorífico Agropecuaria Sonorense, S. de R.L. de C.V.) | D23: Hermosillo | E23: Sonora | F23: Calle de la Plata S/N, Parque Industrial, C.P. 83299 | G23: ND | H23: https://campo.nl.gob.mx/pdf/directorios/Directorio_TIF.pdf | https://en.grupobachoco.com/wp-content/downloads/2023/Bachoco-Norson-July-2023-ENG.pdf | https://expansion.mx/empresas/2023/07/12/bachoco-concluye-compra-norson-holding | I23: 2024 (año indicado en el documento; fecha exacta ND) | 2023-07-12 | 2023-07-12 | J23: Hipótesis | K23: No | L23: - | M23: Sin cuenta del CRM identificada como Norson. | N23: =SUMIFS('Cuentas CRM y homologación'!$P$2:$P$22,'Cuentas CRM y homologación'!$W$2:$W$22,$A23) -> 0 | O23: =SUMIFS('Cuentas CRM y homologación'!$Q$2:$Q$22,'Cuentas CRM y homologación'!$W$2:$W$22,$A23) -> 0 | P23: =SUMIFS('Cuentas CRM y homologación'!$R$2:$R$22,'Cuentas CRM y homologación'!$W$2:$W$22,$A23) -> 0 | Q23: =SUMIFS('Cuentas CRM y homologación'!$S$2:$S$22,'Cuentas CRM y homologación'!$W$2:$W$22,$A23) -> 0 | R23: =SUMIFS('Cuentas CRM y homologación'!$T$2:$T$22,'Cuentas CRM y homologación'!$W$2:$W$22,$A23) -> 0 | S23: Pertenece a Bachoco desde la compra de Norson (jul-2023), pero la razón social en SENASICA no dice Norson: hipótesis. | T23: Evidencia débil: confirmar antes de dar de alta.
A24: BCH-033 | B24: Planta porcina (rastro TIF) | C24: Rastro porcino/bovino TIF 62 (Norson; razón social en SENASICA: Promotora Comercial Alpro, S. de R.L. de C.V.) | D24: Hermosillo | E24: Sonora | F24: Boulevard de los Ganaderos S/N, Sector Industrial Presa, C.P. 83293 | G24: ND | H24: https://campo.nl.gob.mx/pdf/directorios/Directorio_TIF.pdf | https://en.grupobachoco.com/wp-content/downloads/2023/Bachoco-Norson-July-2023-ENG.pdf | I24: 2024 (año indicado en el documento; fecha exacta ND) | 2023-07-12 | J24: Hipótesis | K24: No | L24: - | M24: Sin cuenta del CRM identificada como Norson. | N24: =SUMIFS('Cuentas CRM y homologación'!$P$2:$P$22,'Cuentas CRM y homologación'!$W$2:$W$22,$A24) -> 0 | O24: =SUMIFS('Cuentas CRM y homologación'!$Q$2:$Q$22,'Cuentas CRM y homologación'!$W$2:$W$22,$A24) -> 0 | P24: =SUMIFS('Cuentas CRM y homologación'!$R$2:$R$22,'Cuentas CRM y homologación'!$W$2:$W$22,$A24) -> 0 | Q24: =SUMIFS('Cuentas CRM y homologación'!$S$2:$S$22,'Cuentas CRM y homologación'!$W$2:$W$22,$A24) -> 0 | R24: =SUMIFS('Cuentas CRM y homologación'!$T$2:$T$22,'Cuentas CRM y homologación'!$W$2:$W$22,$A24) -> 0 | S24: Misma observación que BCH-032. | T24: Evidencia débil: confirmar antes de dar de alta.
A25: BCH-040 | B25: Valor agregado | C25: Trosi de Carne, S.A. de C.V. (Trosi) | D25: Monterrey | E25: Nuevo León | F25: PENDIENTE | G25: ND | H25: https://www.bmv.com.mx/docs-pub/infoanua/infoanua_1378033_2023_1.pdf | I25: 2024-04/05 (fecha exacta ND) | J25: Hipótesis | K25: No | L25: - | M25: Sin cuenta del CRM en Monterrey identificada como Trosi. | N25: =SUMIFS('Cuentas CRM y homologación'!$P$2:$P$22,'Cuentas CRM y homologación'!$W$2:$W$22,$A25) -> 0 | O25: =SUMIFS('Cuentas CRM y homologación'!$Q$2:$Q$22,'Cuentas CRM y homologación'!$W$2:$W$22,$A25) -> 0 | P25: =SUMIFS('Cuentas CRM y homologación'!$R$2:$R$22,'Cuentas CRM y homologación'!$W$2:$W$22,$A25) -> 0 | Q25: =SUMIFS('Cuentas CRM y homologación'!$S$2:$S$22,'Cuentas CRM y homologación'!$W$2:$W$22,$A25) -> 0 | R25: =SUMIFS('Cuentas CRM y homologación'!$T$2:$T$22,'Cuentas CRM y homologación'!$W$2:$W$22,$A25) -> 0 | S25: Domicilio pendiente. | T25: Evidencia débil: confirmar antes de dar de alta.
A26: BCH-041 | B26: Valor agregado | C26: RYC Alimentos, S.A. de C.V. (2 plantas multiproteína) | D26: Puebla | E26: Puebla | F26: PENDIENTE | G26: ND | H26: https://www.sec.gov/Archives/edgar/data/1044896/000141057822001105/iba-20211231x20f.htm | https://www.bmv.com.mx/docs-pub/infoanua/infoanua_1378033_2023_1.pdf | I26: 2022-04-29 | 2024-04/05 (fecha exacta ND) | J26: Confirmado | K26: No | L26: - | M26: Sin cuenta del CRM en Puebla identificada como RYC. | N26: =SUMIFS('Cuentas CRM y homologación'!$P$2:$P$22,'Cuentas CRM y homologación'!$W$2:$W$22,$A26) -> 0 | O26: =SUMIFS('Cuentas CRM y homologación'!$Q$2:$Q$22,'Cuentas CRM y homologación'!$W$2:$W$22,$A26) -> 0 | P26: =SUMIFS('Cuentas CRM y homologación'!$R$2:$R$22,'Cuentas CRM y homologación'!$W$2:$W$22,$A26) -> 0 | Q26: =SUMIFS('Cuentas CRM y homologación'!$S$2:$S$22,'Cuentas CRM y homologación'!$W$2:$W$22,$A26) -> 0 | R26: =SUMIFS('Cuentas CRM y homologación'!$T$2:$T$22,'Cuentas CRM y homologación'!$W$2:$W$22,$A26) -> 0 | S26: RYC Alimentos pertenece a Bachoco desde ene-2022 (2 plantas multiproteína en Puebla); domicilios pendientes. | T26: Fuente confirmada: candidato a dar de alta si interesa.
A27: BCH-042 | B27: Alimento para mascotas | C27: Proveedora La Perla, S.A. de C.V. (alimento para mascotas) | D27: PENDIENTE (Querétaro) | E27: Querétaro | F27: PENDIENTE | G27: ND | H27: https://www.bmv.com.mx/docs-pub/infoanua/infoanua_1378033_2023_1.pdf | https://www.sec.gov/Archives/edgar/data/1044896/000141057822001105/iba-20211231x20f.htm | I27: 2024-04/05 (fecha exacta ND) | 2022-04-29 | J27: Confirmado | K27: No | L27: - | M27: Sin cuenta del CRM identificada como La Perla. | N27: =SUMIFS('Cuentas CRM y homologación'!$P$2:$P$22,'Cuentas CRM y homologación'!$W$2:$W$22,$A27) -> 0 | O27: =SUMIFS('Cuentas CRM y homologación'!$Q$2:$Q$22,'Cuentas CRM y homologación'!$W$2:$W$22,$A27) -> 0 | P27: =SUMIFS('Cuentas CRM y homologación'!$R$2:$R$22,'Cuentas CRM y homologación'!$W$2:$W$22,$A27) -> 0 | Q27: =SUMIFS('Cuentas CRM y homologación'!$S$2:$S$22,'Cuentas CRM y homologación'!$W$2:$W$22,$A27) -> 0 | R27: =SUMIFS('Cuentas CRM y homologación'!$T$2:$T$22,'Cuentas CRM y homologación'!$W$2:$W$22,$A27) -> 0 | S27: Planta de alimento para mascotas en Querétaro; municipio y domicilio pendientes. | T27: Fuente confirmada: candidato a dar de alta si interesa.
A28: BCH-050 | B28: Alimento balanceado | C28: Planta CAMPI Mérida | D28: Mérida | E28: Yucatán | F28: Calle 17 No. 400x20, Ciudad Industrial | G28: 40 toneladas/hora | H28: https://campi-alimentos.com/plantas/ | https://campi-alimentos.com/nosotros/ | I28: ND (sin fecha) | ND (sin fecha) | J28: Confirmado | K28: Por confirmar | L28: Bachoco, S.A. de C.V. - Planta De Alimentos 1 Bachoco S.A. De C.V. | M28: La cuenta "Planta De Alimentos 1" (José María Castro SN, Ciudad Industrial, Mérida, CP 97288) coincide en tipo (alimento) y zona (Ciudad Industrial) con la planta CAMPI; las calles no coinciden (Calle 17 No. 400 x 20). | N28: =SUMIFS('Cuentas CRM y homologación'!$P$2:$P$22,'Cuentas CRM y homologación'!$W$2:$W$22,$A28) -> 0 | O28: =SUMIFS('Cuentas CRM y homologación'!$Q$2:$Q$22,'Cuentas CRM y homologación'!$W$2:$W$22,$A28) -> 0 | P28: =SUMIFS('Cuentas CRM y homologación'!$R$2:$R$22,'Cuentas CRM y homologación'!$W$2:$W$22,$A28) -> 0 | Q28: =SUMIFS('Cuentas CRM y homologación'!$S$2:$S$22,'Cuentas CRM y homologación'!$W$2:$W$22,$A28) -> 0 | R28: =SUMIFS('Cuentas CRM y homologación'!$T$2:$T$22,'Cuentas CRM y homologación'!$W$2:$W$22,$A28) -> 0 | S28: Dos cuentas del CRM (la 15 y la 19) caen en la Ciudad Industrial de Mérida (CP 97288) y solo se conoce una planta pública ahí. Confirmar si son la misma. | T28: -
A29: BCH-051 | B29: Alimento balanceado | C29: Planta CAMPI Cuautla | D29: Cuautla | E29: Morelos | F29: Vía de FFCC México-Puebla No. 3, Col. Cuatlixco | G29: 19 toneladas/hora | H29: https://campi-alimentos.com/plantas/ | I29: ND (sin fecha) | J29: Confirmado | K29: Sí | L29: Bachoco S.A de C.V - Cuautla | M29: Mismo municipio, calle y número: CRM "México Puebla 3, Estrella, Cuautla" y CAMPI "Vía de FFCC México-Puebla No. 3, Col. Cuatlixco". La colonia no coincide. | N29: =SUMIFS('Cuentas CRM y homologación'!$P$2:$P$22,'Cuentas CRM y homologación'!$W$2:$W$22,$A29) -> 0 | O29: =SUMIFS('Cuentas CRM y homologación'!$Q$2:$Q$22,'Cuentas CRM y homologación'!$W$2:$W$22,$A29) -> 0 | P29: =SUMIFS('Cuentas CRM y homologación'!$R$2:$R$22,'Cuentas CRM y homologación'!$W$2:$W$22,$A29) -> 0 | Q29: =SUMIFS('Cuentas CRM y homologación'!$S$2:$S$22,'Cuentas CRM y homologación'!$W$2:$W$22,$A29) -> 0 | R29: =SUMIFS('Cuentas CRM y homologación'!$T$2:$T$22,'Cuentas CRM y homologación'!$W$2:$W$22,$A29) -> 0 | S29: Cuenta sin oportunidades registradas. Es planta de alimento balanceado, no de aves. La página de CAMPI no tiene fecha: vigencia no verificada. | T29: -
A30: BCH-052 | B30: Alimento balanceado | C30: Planta CAMPI Chinameca | D30: Chinameca | E30: Veracruz | F30: Calle Altamirano s/n | G30: 20 toneladas/hora | H30: https://campi-alimentos.com/plantas/ | I30: ND (sin fecha) | J30: Confirmado | K30: No | L30: - | M30: Sin cuenta del CRM en Chinameca. | N30: =SUMIFS('Cuentas CRM y homologación'!$P$2:$P$22,'Cuentas CRM y homologación'!$W$2:$W$22,$A30) -> 0 | O30: =SUMIFS('Cuentas CRM y homologación'!$Q$2:$Q$22,'Cuentas CRM y homologación'!$W$2:$W$22,$A30) -> 0 | P30: =SUMIFS('Cuentas CRM y homologación'!$R$2:$R$22,'Cuentas CRM y homologación'!$W$2:$W$22,$A30) -> 0 | Q30: =SUMIFS('Cuentas CRM y homologación'!$S$2:$S$22,'Cuentas CRM y homologación'!$W$2:$W$22,$A30) -> 0 | R30: =SUMIFS('Cuentas CRM y homologación'!$T$2:$T$22,'Cuentas CRM y homologación'!$W$2:$W$22,$A30) -> 0 | S30: Es la presencia verificable de Bachoco en el Istmo; no hay evidencia pública de planta en Tierra Blanca. | T30: Fuente confirmada: candidato a dar de alta si interesa.
A31: BCH-053 | B31: Alimento balanceado | C31: Planta de Alimentos Grupo Bachoco (Operación Monterrey) | D31: Salinas Victoria | E31: Nuevo León | F31: PENDIENTE | G31: ND | H31: https://www.nl.gob.mx/es/boletines/asiste-secretaria-de-medio-ambiente-presentacion-de-inversion-ambiental-de-grupo-bachoco | https://www.notimx.mx/2026/07/bachoco-impulsa-una-operacion-mas.html | I31: 2026-07-22 | 2026-07-23 | J31: Confirmado | K31: No | L31: - | M31: Sin cuenta del CRM en Salinas Victoria. | N31: =SUMIFS('Cuentas CRM y homologación'!$P$2:$P$22,'Cuentas CRM y homologación'!$W$2:$W$22,$A31) -> 0 | O31: =SUMIFS('Cuentas CRM y homologación'!$Q$2:$Q$22,'Cuentas CRM y homologación'!$W$2:$W$22,$A31) -> 0 | P31: =SUMIFS('Cuentas CRM y homologación'!$R$2:$R$22,'Cuentas CRM y homologación'!$W$2:$W$22,$A31) -> 0 | Q31: =SUMIFS('Cuentas CRM y homologación'!$S$2:$S$22,'Cuentas CRM y homologación'!$W$2:$W$22,$A31) -> 0 | R31: =SUMIFS('Cuentas CRM y homologación'!$T$2:$T$22,'Cuentas CRM y homologación'!$W$2:$W$22,$A31) -> 0 | S31: Proyecto ambiental de más de MXN 31 millones ejecutado o presentado en jul-2026 (boletín del Gobierno de Nuevo León); es de control ambiental, no de ampliación. Otra fuente (NotiMx) dice que el monto no se divulgó. | T31: Fuente confirmada: candidato a dar de alta si interesa.
A32: BCH-054 | B32: Alimento balanceado | C32: Planta Forrajera de Querétaro (CAMPI, división Bajío) | D32: PENDIENTE (Querétaro) | E32: Querétaro | F32: PENDIENTE | G32: ND | H32: https://campi-alimentos.com/nosotros/ | I32: ND (sin fecha) | J32: Hipótesis | K32: No | L32: - | M32: Sin cuenta del CRM en Querétaro. | N32: =SUMIFS('Cuentas CRM y homologación'!$P$2:$P$22,'Cuentas CRM y homologación'!$W$2:$W$22,$A32) -> 0 | O32: =SUMIFS('Cuentas CRM y homologación'!$Q$2:$Q$22,'Cuentas CRM y homologación'!$W$2:$W$22,$A32) -> 0 | P32: =SUMIFS('Cuentas CRM y homologación'!$R$2:$R$22,'Cuentas CRM y homologación'!$W$2:$W$22,$A32) -> 0 | Q32: =SUMIFS('Cuentas CRM y homologación'!$S$2:$S$22,'Cuentas CRM y homologación'!$W$2:$W$22,$A32) -> 0 | R32: =SUMIFS('Cuentas CRM y homologación'!$T$2:$T$22,'Cuentas CRM y homologación'!$W$2:$W$22,$A32) -> 0 | S32: Solo un sitio de CAMPI menciona la planta forrajera de Querétaro; sin fecha ni domicilio. | T32: Evidencia débil: confirmar antes de dar de alta.
... A43: BCH-090 | B43: Laboratorio | C43: Laboratorio de vacunas y farmacéuticos veterinarios (PEC LAB; posible vínculo con Pecuarius, no confirmado) | D43: PENDIENTE | E43: PENDIENTE | F43: PENDIENTE | G43: ND | H43: https://www.bmv.com.mx/docs-pub/infoanua/infoanua_1378033_2023_1.pdf | https://bmeditores.mx/avicultura/reconocen-a-grupo-bachoco-en-personalidad-del-sector-pecuario/ | I43: 2024-04/05 (fecha exacta ND) | 2025-03-12 | J43: Pendiente | K43: No | L43: - | M43: Sin cuenta del CRM identificada como laboratorio. | N43: =SUMIFS('Cuentas CRM y homologación'!$P$2:$P$22,'Cuentas CRM y homologación'!$W$2:$W$22,$A43) -> 0 | O43: =SUMIFS('Cuentas CRM y homologación'!$Q$2:$Q$22,'Cuentas CRM y homologación'!$W$2:$W$22,$A43) -> 0 | P43: =SUMIFS('Cuentas CRM y homologación'!$R$2:$R$22,'Cuentas CRM y homologación'!$W$2:$W$22,$A43) -> 0 | Q43: =SUMIFS('Cuentas CRM y homologación'!$S$2:$S$22,'Cuentas CRM y homologación'!$W$2:$W$22,$A43) -> 0 | R43: =SUMIFS('Cuentas CRM y homologación'!$T$2:$T$22,'Cuentas CRM y homologación'!$W$2:$W$22,$A43) -> 0 | S43: Ubicación pendiente. | T43: Sin ubicación publicada.

Sheet Cuentas CRM y homologación
A1: N° | B1: Cuenta en el CRM (nombre actual) | C1: Municipio (según domicilio) | D1: Estado | E1: Zona | F1: Domicilio registrado en el CRM | G1: Propietario CRM (histórico) | H1: Propietarios que aparecen en sus oportunidades | I1: Segmentación actual | J1: End Market actual | K1: Subcategoría actual | L1: Industria primaria actual | M1: Fecha de creación | N1: Creada por | O1: Contacto principal registrado | P1: Ganadas (todo el CRM) | Q1: Perdidas (todo el CRM) | R1: Abiertas (todo el CRM) | S1: Ganadas Elegibles | T1: Perdidas Elegibles | U1: Última ganada (todo el CRM) | V1: Problemas detectados (todos CONFIRMADO en el CRM) | W1: Sitio público asociado (ver hoja Plantas vs CRM) | X1: Base del cruce con el sitio público | Y1: PROPUESTA: nombre | Z1: PROPUESTA: End Market | AA1: PROPUESTA: Subcategoría | AB1: PROPUESTA: Segmentación | AC1: Acción sugerida y quién decide
A2: 1 | B2: Bachoco | C2: Ciudad Obregón | D2: Sonora | E2: Noroeste (Sonora/BC) | F2: Internacional 1848, 85065 Ciudad Obregón, Sonora,85065 CIUDAD OBREGON, SONORA,MEXICO | G2: Cesar Vázquez | H2: Johnatan Inactive Murillo | I2: End User | J2: Food & Beverage | K2: Manufacturing - Food Processing | L2: (vacío) | M2: 10-3-2023 12:20 PM | N2: Johnatan.MurilloVelarde | O2: No | P2: =COUNTIFS(Oportunidades!$C$2:$C$71,$B2,Oportunidades!$H$2:$H$71,"Ganada") -> 0 | Q2: =COUNTIFS(Oportunidades!$C$2:$C$71,$B2,Oportunidades!$H$2:$H$71,"Perdida") -> 2 | R2: =COUNTIFS(Oportunidades!$C$2:$C$71,$B2,Oportunidades!$H$2:$H$71,"Abierta") -> 0 | S2: =COUNTIFS(Oportunidades!$C$2:$C$71,$B2,Oportunidades!$H$2:$H$71,"Ganada",Oportunidades!$Z$2:$Z$71,"Elegible") -> 0 | T2: =COUNTIFS(Oportunidades!$C$2:$C$71,$B2,Oportunidades!$H$2:$H$71,"Perdida",Oportunidades!$Z$2:$Z$71,"Elegible") -> 1 | U2: =IF(P2=0,"-",_xlfn.MAXIFS(Oportunidades!$I$2:$I$71,Oportunidades!$C$2:$C$71,$B2,Oportunidades!$H$2:$H$71,"Ganada")) -> - | V2: Propietario no aparece en la hoja Team del archivo IR: confirmar vigencia; Sin contacto principal; Sin correo del contacto principal; Sin teléfono | W2: BCH-080 | X2: Por confirmar. La cuenta "Bachoco" (Av. Internacional 1848, Cd. Obregón) coincide en municipio con el CEDIS; la fuente no da domicilio. | Y2: Bachoco, S.A. de C.V. - Ciudad Obregón | Z2: Food & Beverage | AA2: Manufacturing - Food Processing | AB2: End User | AC2: Confirmar con quien la lleva (su propietario no aparece en la hoja Team) qué instalación es; revisar si es duplicada de la cuenta 8. Decide: dueño de la cuenta y administrador del CRM.
A3: 2 | B3: BACHOCO S.A. DE C.V. | C3: Celaya | D3: Guanajuato | E3: Bajío (Celaya) | F3: Av. Norte 11 Esq. Poniente 4 Cd. Industrial Celaya, Gto.,38010 CELAYA GTO, GUANAJUATO,MEXICO | G3: Ulises Sanchez | H3: Froylan Santiago Inactive Alcántara | I3: End User | J3: Food & Beverage | K3: Manufacturing - Food Processing | L3: (vacío) | M3: 6-1-2021 09:30 AM | N3: DATA.MIGRATION | O3: Sí | P3: =COUNTIFS(Oportunidades!$C$2:$C$71,$B3,Oportunidades!$H$2:$H$71,"Ganada") -> 3 | Q3: =COUNTIFS(Oportunidades!$C$2:$C$71,$B3,Oportunidades!$H$2:$H$71,"Perdida") -> 0 | R3: =COUNTIFS(Oportunidades!$C$2:$C$71,$B3,Oportunidades!$H$2:$H$71,"Abierta") -> 0 | S3: =COUNTIFS(Oportunidades!$C$2:$C$71,$B3,Oportunidades!$H$2:$H$71,"Ganada",Oportunidades!$Z$2:$Z$71,"Elegible") -> 0 | T3: =COUNTIFS(Oportunidades!$C$2:$C$71,$B3,Oportunidades!$H$2:$H$71,"Perdida",Oportunidades!$Z$2:$Z$71,"Elegible") -> 0 | U3: =IF(P3=0,"-",_xlfn.MAXIFS(Oportunidades!$I$2:$I$71,Oportunidades!$C$2:$C$71,$B3,Oportunidades!$H$2:$H$71,"Ganada")) -> 44527 | W3: Sin sitio público identificado | X3: Misma Ciudad Industrial de Celaya que la oficina corporativa (BCH-001), pero otro domicilio (Av. Norte 11 esq. Poniente 4). Ninguna fuente pública ubica una instalación ahí. | Y3: Bachoco, S.A. de C.V. - Celaya - [tipo por confirmar] | Z3: Food & Beverage | AA3: Manufacturing - Food Processing | AB3: End User | AC3: Preguntar a quien lleva la cuenta (propietario en el CRM: Ulises Sánchez; confirmar que sigue activo) si es un sitio distinto o duplicado de la cuenta Corp. Comparte contacto principal con Corp y con la cuenta 6. La planta de rendimiento BCH-020 tiene el mismo CP 38010, pero eso no basta para ligarla.
A4: 3 | B4: Bachoco, S.A. De C.V. - Tecamachalco | C4: Tecamachalco | D4: Puebla | E4: Puebla (Tecamachalco) | F4: México 150, Barrio de San Juan,,75484 TECAMACHALCO, PUEBLA,MEXICO | G4: Eliasib Luna | H4: Eliasib Luna; Alejandro Avila | I4: End User | J4: Food & Beverage | K4: Manufacturing - Food Processing | L4: (vacío) | M4: 6-1-2021 09:39 AM | N4: DATA.MIGRATION | O4: Sí | P4: =COUNTIFS(Oportunidades!$C$2:$C$71,$B4,Oportunidades!$H$2:$H$71,"Ganada") -> 10 | Q4: =COUNTIFS(Oportunidades!$C$2:$C$71,$B4,Oportunidades!$H$2:$H$71,"Perdida") -> 5 | R4: =COUNTIFS(Oportunidades!$C$2:$C$71,$B4,Oportunidades!$H$2:$H$71,"Abierta") -> 0 | S4: =COUNTIFS(Oportunidades!$C$2:$C$71,$B4,Oportunidades!$H$2:$H$71,"Ganada",Oportunidades!$Z$2:$Z$71,"Elegible") -> 10 | T4: =COUNTIFS(Oportunidades!$C$2:$C$71,$B4,Oportunidades!$H$2:$H$71,"Perdida",Oportunidades!$Z$2:$Z$71,"Elegible") -> 3 | U4: =IF(P4=0,"-",_xlfn.MAXIFS(Oportunidades!$I$2:$I$71,Oportunidades!$C$2:$C$71,$B4,Oportunidades!$H$2:$H$71,"Ganada")) -> 46216 | W4: BCH-014 | X4: Por confirmar. El predio oficial del rastro está en San Salvador Huixcolotla (Km 53 Puebla-Tehuacán, CP 75440); "Tecamachalco" es el nombre histórico del complejo. La cuenta del CRM dice Tecamachalco, Barrio de San Juan (CP 75484), domicilio que viene de directorios no oficiales. | Y4: Bachoco, S.A. de C.V. - Tecamachalco (o San Salvador Huixcolotla si se confirma que es el rastro) | Z4: Food & Beverage | AA4: Manufacturing - Food Processing | AB4: End User | AC4: Confirmar en visita el domicilio real del sitio atendido. Es la cuenta con ganadas más recientes (jul-2026).
A5: 4 | B5: Bachoco S.A. de C.V. - Corp | C5: Celaya | D5: Guanajuato | E5: Bajío (Celaya) | F5: Av. Tecnológico N° 401, Ciudad Industrial,38010 CELAYA, GUANAJUATO,MEXICO | G5: Ulises Sanchez | H5: Ulises Sanchez | I5: End User | J5: Food & Beverage | K5: Manufacturing - Food Processing | L5: (vacío) | M5: 6-1-2021 09:45 AM | N5: DATA.MIGRATION | O5: Sí | P5: =COUNTIFS(Oportunidades!$C$2:$C$71,$B5,Oportunidades!$H$2:$H$71,"Ganada") -> 1 | Q5: =COUNTIFS(Oportunidades!$C$2:$C$71,$B5,Oportunidades!$H$2:$H$71,"Perdida") -> 0 | R5: =COUNTIFS(Oportunidades!$C$2:$C$71,$B5,Oportunidades!$H$2:$H$71,"Abierta") -> 0 | S5: =COUNTIFS(Oportunidades!$C$2:$C$71,$B5,Oportunidades!$H$2:$H$71,"Ganada",Oportunidades!$Z$2:$Z$71,"Elegible") -> 1 | T5: =COUNTIFS(Oportunidades!$C$2:$C$71,$B5,Oportunidades!$H$2:$H$71,"Perdida",Oportunidades!$Z$2:$Z$71,"Elegible") -> 0 | U5: =IF(P5=0,"-",_xlfn.MAXIFS(Oportunidades!$I$2:$I$71,Oportunidades!$C$2:$C$71,$B5,Oportunidades!$H$2:$H$71,"Ganada")) -> 43946 | W5: BCH-001 | X5: Sí. Domicilio coincide: Av. Tecnológico No. 401, Ciudad Industrial, CP 38010, Celaya (cuenta "Corp"). La verificó la lista pública con el Reporte Anual 2023, el perfil de la BMV y el aviso de privacidad de bachoco.com. | Y5: Bachoco, S.A. de C.V. - Celaya - Corporativo | Z5: Food & Beverage | AA5: Manufacturing - Food Processing | AB5: End User | AC5: Dejar como cuenta corporativa. Pregunta para el administrador del CRM: ¿la segmentación correcta de una cuenta corporativa es "Corporate" o "End User"? Hoy la de Culiacán dice Corporate y esta dice End User.
